# üêõ Bug Fix: Import Error - UserModel

## Issue
```
ImportError: cannot import name 'User' from 'app.models.user_model'
```

## Root Cause
The new route files (`resource_routes.py`, `meeting_routes.py`, `chat_routes.py`, `notification_routes.py`) were importing `User` from `user_model.py`, but the actual model class is named `UserModel`.

## Files Fixed

### 1. **resource_routes.py**
```python
# Before
from app.models.user_model import User

# After
from app.models.user_model import UserModel
```

### 2. **meeting_routes.py**
```python
# Before
from app.models.user_model import User

# After
from app.models.user_model import UserModel
```

### 3. **chat_routes.py**
```python
# Before
from app.models.user_model import User

# After
from app.models.user_model import UserModel
```

### 4. **notification_routes.py**
```python
# Before
from app.models.user_model import User

# After
from app.models.user_model import UserModel
```

### 5. **All Type Annotations (20+ occurrences)**
```python
# Before
current_user: User = Depends(get_current_user)

# After
current_user: UserModel = Depends(get_current_user)
```

## Verification

‚úÖ **Server starts successfully:**
```bash
cd backend
python start_server.py
```

‚úÖ **Output:**
```
INFO:     Uvicorn running on http://0.0.0.0:8000 (Press CTRL+C to quit)
2025-10-14 18:49:32,059 [INFO] app.core.database: Successfully connected to MongoDB
INFO:     Application startup complete.
```

‚úÖ **API Documentation available at:**
- http://localhost:8000/docs

## Note
There is a non-critical warning:
```
[WARNING] app.services.ml_service: Could not import RecommendationModel from ml module. Using fallback model.
```

This is expected and does not affect functionality - the ML service uses a fallback model implementation.

## Status
üü¢ **FIXED** - Server now starts without errors!

---
**Fixed:** October 14, 2025  
**Issue Type:** Import Error  
**Severity:** Critical (blocking server startup)  
**Resolution Time:** < 5 minutes
